<!DOCTYPE html>
<html lang="en">

<head>
    <meta charset="utf-8">
    <title>Generator --- throw&return</title>
</head>

<body>
    <script type="text/javascript">
    function show(arr) {
        console.log("");
        arr.forEach(function(key, i) {
            console.log(i + "", key);
        });
        console.log("");
    }


    //////////////////////////////////
    // Generator.prototype.throw() //
    //////////////////////////////////

    /*Generator 函数返回的遍历器对象，都有一个throw方法，可以在函数体外抛出错误，然后在 Generator 函数体内捕获。*/
    {
        let g = function*() {
            yield;
            try {
                yield;
            } catch (e) {
                console.log('内部捕获', e);
            }
        };

        let i = g();
        i.next();
        i.next();

        try {
            i.throw(new Error("错误A"));
            i.throw(new Error("错误B"));
        } catch (e) {
            console.log('外部捕获', e);
        }
        // 内部捕获 Error: 错误A
        // 外部捕获 Error: 错误B
        // i第二次抛出错误，由于 Generator 函数内部的catch语句已经执行过了，不会再捕捉到这个错误了，所以这个错误就被抛出了 Generator 函数体，被函数体外的catch语句捕获。



        try {
            throw new Error('a');
            throw new Error('b');
        } catch (e) {
            console.log('外部捕获', e);
        }
        // 外部捕获 Error: a
        // 由于不是使用 Generator 实例的throw方法所以都是外部;第二次抛出错误由于catch语句已经执行了,所以不会再捕捉
    }


    /*Generator 函数体外抛出的错误，可以在函数体内捕获；反过来，Generator 函数体内抛出的错误，也可以被函数体外的catch捕获。   */
    {
        function* foo() {
            var x = yield 3;
            var y = x.toUpperCase();
            yield y;
        }

        var it = foo();
        it.next(); // { value:3, done:false }

        try {
            it.next(42);
        } catch (err) {
            console.log(err);
        }
        // Uncaught TypeError: console.err is not a function
    }



    // 一旦 Generator 执行过程中抛出错误，且没有被内部捕获，就不会再执行下去了。如果此后还调用next方法，将返回一个value属性等于undefined、done属性等于true的对象，即 JavaScript 引擎认为这个 Generator 已经运行结束了。
    {
        function* g() {
            yield 1;
            console.log('throwing an exception');
            // try {
            throw new Error('generator broke!');
            // } catch (err) {
            // console.log(err)
            // }
            yield 2;
            yield 3;
        }

        function log(generator) {
            var v;
            console.log('starting generator');
            try {
                v = generator.next();
                console.log('第一次运行next方法', v);
            } catch (err) {
                console.log('捕捉错误', v);
            }
            try {
                v = generator.next();
                console.log('第二次运行next方法', v);
            } catch (err) {
                console.log('捕捉错误', v);
            }
            try {
                v = generator.next();
                console.log('第三次运行next方法', v);
            } catch (err) {
                console.log('捕捉错误', v);
            }
            console.log('caller done');
        }

        log(g());
        // starting generator
        // 第一次运行next方法 { value: 1, done: false }
        // throwing an exception
        // 捕捉错误 { value: 1, done: false }
        // 第三次运行next方法 { value: undefined, done: true }
        // caller done

    }




    //////////////////////////////////
    // Generator.prototype.return() //
    //////////////////////////////////

    /*Generator函数返回的遍历器对象，还有一个return方法，可以返回给定的值，并且终结遍历Generator函数。*/
    {
        function* gen() {
            yield 1;
            yield 2;
            yield 3;
        }

        var g = gen();

        show([
            g.next(), // { value: 1, done: false }
            g.return('foo'), // { value: "foo", done: true }
            g.next() // { value: undefined, done: true }
        ]);
    }
    /*如果return方法调用时，不提供参数，则返回值的value属性为undefined。*/
    {
        function* gen() {
            yield 1;
            yield 2;
            yield 3;
        }

        var g = gen();

        show([
            g.return(), // { value: undefined, done: true }
            g.next() // { value: undefined, done: true }
        ]);
    }


    /*如果Generator函数内部有try...finally代码块，那么return方法会推迟到finally代码块执行完再执行*/
    {
        function* numbers() {
            yield 1;
            try {
                yield 2;
                yield 3;
            } finally {
                yield 4;
                yield 5;
            }
            yield 6;
        }
        var g = numbers();
        show([
            g.next(), // { value: 1, done: false }
            g.next(), // { value: 2, done: false } // 进入了try ...catch 语句
            g.return(7), // { value: 4, done: false }
            g.next(), // { value: 5, done: false }
            g.next() // { value: 7, done: true }
        ]);
    }

    // end
    </script>
</body>

</html>
