<!DOCTYPE html>
<html lang="en">

<head>
    <meta charset="UTF-8">
    <title>Promise---Promise.prototype.then</title>
</head>

<body>
    <script type="text/javascript">
    function show(arr) {
        console.log("");
        arr.forEach(function(key, i) {
            console.log(i + "", key);
        });
        console.log("");
    }

    // 当Promise对象状态为fulfilled时，调用 then 的 onfulfilled 方法，当Promise对象状态为rejected时，调用 then 的 onrejected 方法

    /**
     * Promise.prototype.then()
     */

    /**
     * then() 方法返回一个  Promise。它最多需要有两个参数：Promise的成功和失败情况的回调函数。
     *
     * 注意事项：如果省略这两个参数，或者提供非函数，那么将创建一个没有其他处理程序的新Promise，只是采用 Promise 的最终状态，then 被调用。如果省略第一个参数或提供的不是函数，创建的新 Promise 简单地采用 Promise 的完成状态(包括值)，then被调用（如果它变为完成）。如果省略第二个参数或提供的不是函数，创建的新 Promise 简单地采用 Promise 的拒绝状态(包括值)，then被调用（如果它被拒绝）。



        p.then(onFulfilled, onRejected);

        p.then(function(value) {
           // fulfillment
          }, function(reason) {
          // rejection
        });

        参数

        then 返回一个由输入函数确定的Promise：
            如果 onFulfilled  或者 onRejected 抛出一个错误，或者返回一个拒绝的 Promise ，then 返回一个 rejected Promise。
            如果 onFulfilled  或者 onRejected 返回一个 resolves Promise，或者返回任何其他值，then 返回一个 resolved Promise。

        onFulfilled
            一个 Function被调用， 当 Promise 满足时. 该函数有一个参数，即 fulfillment 值。即是Resolved状态的回调函数

        onRejected
            一个 Function被调用， 当 Promise 被拒绝时. 该函数有一个参数, 拒绝的 reason。即是Rejected状态的回调函数。

        返回值
            一个 Promise.
            then方法返回的是一个新的Promise实例（注意，不是原来那个Promise实例）。因此可以采用链式写法，即then方法后面再调用另一个then方法。
     */

    // 就是说返回的 Promise对象的状态 不是由这个then的 "onFulfilled回调函数" 还是 "onRejected回调函数" 调用 ; 而是 "onFulfilled回调函数或者onRejected回调函数" 调用时是否发生错误 是否直接返回 "拒绝的 Promise"
    {
        // 例子1
        function ran(n, flag = true) {
            return new Promise(function(resolve, reject) {
                if (flag) {
                    resolve(n + "次resolve");
                } else {
                    reject(n + "次reject");
                }
            });
        }

        ran(1, false).then( // 第一个 then
            success => {
                console.log("第" + success + "成功");
                return ran(2);
            },
            error => {
                console.log("第" + error + "失败");
                return ran(2);
            }
        ).then( // 第二个 then
            success => {
                console.log("第" + success + "成功");
                return ran(3);
            },
            error => {
                console.log("第" + error + "失败");
                return ran(3);
            }
        ).catch( // 第三个 then
            error => {
                console.log("第" + error + "失败");
            }
        ); // 在done() 未实现的情况下 链式操作最后最好是catch收尾。

        // 第1次reject失败 第一个then是执行onRejected回调函数
        // 第2次resolve成功 第一个then虽然是执行onRejected回调函数 但是 函数体里面返回的 Promise是resolve状态 , 所以在第二个then里面是执行的是 onFulfilled回调函数
    }

    {
        // 例子二
        let p = new Promise(function(resolve, reject) {
            resolve("成功了");
        });
        p.then(function(value){
            console.log("例子二",value);
        }).then(function(value){ // 由于上一个then 里面的  onFulfilled  和 onRejected 都没有返回值 , 即返回任何其他值 , 所以then 返回一个 resolved Promise ; 但是value为undefined
            console.log("例子二",value);
        }).then(function(value){ // 理同上
            console.log("例子二",value);
        });

    }


















    /**
     * Promise.prototype.catch
     *
     * Promise.prototype.catch方法是.then(null, rejection)的别名，用于指定发生错误时的回调函数。
     *
     */

    {
        new Promise(function(rs, rj) {
            rj("错误");
        }).catch((err) => console.log('rejected', err)); // rejected 错误

        // 等同于
        new Promise(function(rs, rj) {
            rj("错误");
        }).then(null, (err) => console.log("rejected:", err)); // rejected: 错误
    }



    /*如果省略这两个参数，或者提供非函数*/
    {
        let p1 = Promise.resolve('foo');
        let p2 = p1
            .then(console.log("haha1"))
            .then(console.log("haha2"))
            .then(console.log("haha3"))
            .then(console.log("haha4"))
            .then(console.log("haha5"));
        p2.then(value => {
            console.log("成功", value, p1, p2, p1 == p2);
        }, error => {
            console.log("错误", error, p1, p2, p1 == p2);
        });
    } {
        let p1 = Promise.reject('foo');
        let p2 = p1
            .then(value => {
                console.log(value, p1, p2, p1 == p2)
            })
            .then(console.log("haha2"))
            .then(console.log("haha3"))
            .then(console.log("haha4"))
            .then(console.log("haha5"));
        p2.then(value => {
            console.log("成功", value, p1, p2, p1 == p2);
        }, error => {
            console.log("错误", error, p1, p2, p1 == p2);
        });
    }
    // 如果一直没有onFulfilled 或者 onRejected处理 ; 状态和传的值会一直链式传下去 直到被then里面的onFulfilled 或者 onRejected

    // catch同理
    {
        let p1 = Promise.reject('foo')
            .then(value => {
                console.log(value, p1, p2, p1 == p2)
            })
            .then(console.log("haha2"))
            .then(console.log("haha3"))
            .then(console.log("haha4"))
            .then(console.log("haha5"))
            .catch(error => {
                console.log("错误", error);
            });
    }

    // 就是说一直没有对应的处理函数处理Promise状态 , 会留给下一个then 或者 catch处理 , 状态和值都会一直传下去
    </script>
</body>

</html>
